try{

}
catch(const InvalidUserException& expected)
{

}